Workbook

Sheet Data
A1: Datum | B1: CPI (original) | C1: INDPRO (original) | D1: År
A2: 17168 | B2: 21.48 | C2: 13.6792 | D2: =YEAR(A2) -> 1947
A3: 17199 | B3: 21.62 | C3: 13.76 | D3: =YEAR(A3) -> 1947
A4: 17227 | B4: 22 | C4: 13.8407 | D4: =YEAR(A4) -> 1947
A5: 17258 | B5: 22 | C5: 13.733 | D5: =YEAR(A5) -> 1947
A6: 17288 | B6: 21.95 | C6: 13.7869 | D6: =YEAR(A6) -> 1947
A7: 17319 | B7: 22.08 | C7: 13.7869 | D7: =YEAR(A7) -> 1947
A8: 17349 | B8: 22.23 | C8: 13.7061 | D8: =YEAR(A8) -> 1947
A9: 17380 | B9: 22.4 | C9: 13.7869 | D9: =YEAR(A9) -> 1947
A10: 17411 | B10: 22.84 | C10: 13.8946 | D10: =YEAR(A10) -> 1947
A11: 17441 | B11: 22.91 | C11: 14.0292 | D11: =YEAR(A11) -> 1947
A12: 17472 | B12: 23.06 | C12: 14.2177 | D12: =YEAR(A12) -> 1947
A13: 17502 | B13: 23.41 | C13: 14.2716 | D13: =YEAR(A13) -> 1947
... A946: 45901 | B946: 324.245 | C946: 101.668 | D946: =YEAR(A946) -> 2025
A947: 45931 | C947: 101.2075 | D947: =YEAR(A947) -> 2025
A948: 45962 | B948: 325.063 | C948: 101.3605 | D948: =YEAR(A948) -> 2025
A949: 45992 | B949: 326.031 | C949: 101.6781 | D949: =YEAR(A949) -> 2025
A950: 46023 | B950: 326.588 | C950: 102.3963 | D950: =YEAR(A950) -> 2026
A951: 46054 | B951: 327.46 | C951: 102.551 | D951: =YEAR(A951) -> 2026

Sheet Parametrar
A1: Nyckel | B1: Värde
A2: Basår | B2: 2017
A3: Bastyp | B3: Årsgenomsnitt
A4: CPI bas (årsgenomsnitt) | B4: =AVERAGEIFS(Data!B:B,Data!D:D,Parametrar!B2) -> 245.121
A5: INDPRO bas (årsgenomsnitt) | B5: =AVERAGEIFS(Data!C:C,Data!D:D,Parametrar!B2) -> 99.999992

Sheet Rebaserat_Basår
A1: Datum | B1: CPI (Basår=100) | C1: INDPRO (Basår=100)
A2: =Data!A2 -> 17168 | B2: =IF(Data!B2="","",Data!B2*100/Parametrar!B4) -> 8.7630191 | C2: =IF(Data!C2="","",Data!C2*100/Parametrar!B5) -> 13.679201
A3: =Data!A3 -> 17199 | B3: =IF(Data!B3="","",Data!B3*100/Parametrar!B4) -> 8.8201337 | C3: =IF(Data!C3="","",Data!C3*100/Parametrar!B5) -> 13.760001
A4: =Data!A4 -> 17227 | B4: =IF(Data!B4="","",Data!B4*100/Parametrar!B4) -> 8.9751592 | C4: =IF(Data!C4="","",Data!C4*100/Parametrar!B5) -> 13.840701
A5: =Data!A5 -> 17258 | B5: =IF(Data!B5="","",Data!B5*100/Parametrar!B4) -> 8.9751592 | C5: =IF(Data!C5="","",Data!C5*100/Parametrar!B5) -> 13.733001
A6: =Data!A6 -> 17288 | B6: =IF(Data!B6="","",Data!B6*100/Parametrar!B4) -> 8.9547611 | C6: =IF(Data!C6="","",Data!C6*100/Parametrar!B5) -> 13.786901
A7: =Data!A7 -> 17319 | B7: =IF(Data!B7="","",Data!B7*100/Parametrar!B4) -> 9.0077961 | C7: =IF(Data!C7="","",Data!C7*100/Parametrar!B5) -> 13.786901
A8: =Data!A8 -> 17349 | B8: =IF(Data!B8="","",Data!B8*100/Parametrar!B4) -> 9.0689904 | C8: =IF(Data!C8="","",Data!C8*100/Parametrar!B5) -> 13.706101
A9: =Data!A9 -> 17380 | B9: =IF(Data!B9="","",Data!B9*100/Parametrar!B4) -> 9.1383439 | C9: =IF(Data!C9="","",Data!C9*100/Parametrar!B5) -> 13.786901
A10: =Data!A10 -> 17411 | B10: =IF(Data!B10="","",Data!B10*100/Parametrar!B4) -> 9.3178471 | C10: =IF(Data!C10="","",Data!C10*100/Parametrar!B5) -> 13.894601
A11: =Data!A11 -> 17441 | B11: =IF(Data!B11="","",Data!B11*100/Parametrar!B4) -> 9.3464044 | C11: =IF(Data!C11="","",Data!C11*100/Parametrar!B5) -> 14.029201
A12: =Data!A12 -> 17472 | B12: =IF(Data!B12="","",Data!B12*100/Parametrar!B4) -> 9.4075987 | C12: =IF(Data!C12="","",Data!C12*100/Parametrar!B5) -> 14.217701
A13: =Data!A13 -> 17502 | B13: =IF(Data!B13="","",Data!B13*100/Parametrar!B4) -> 9.5503853 | C13: =IF(Data!C13="","",Data!C13*100/Parametrar!B5) -> 14.271601
A14: =Data!A14 -> 17533 | B14: =IF(Data!B14="","",Data!B14*100/Parametrar!B4) -> 9.660535 | C14: =IF(Data!C14="","",Data!C14*100/Parametrar!B5) -> 14.352401
A15: =Data!A15 -> 17564 | B15: =IF(Data!B15="","",Data!B15*100/Parametrar!B4) -> 9.6564554 | C15: =IF(Data!C15="","",Data!C15*100/Parametrar!B5) -> 14.379301
A16: =Data!A16 -> 17593 | B16: =IF(Data!B16="","",Data!B16*100/Parametrar!B4) -> 9.5871019 | C16: =IF(Data!C16="","",Data!C16*100/Parametrar!B5) -> 14.217701
A17: =Data!A17 -> 17624 | B17: =IF(Data!B17="","",Data!B17*100/Parametrar!B4) -> 9.7176497 | C17: =IF(Data!C17="","",Data!C17*100/Parametrar!B5) -> 14.244701
A18: =Data!A18 -> 17654 | B18: =IF(Data!B18="","",Data!B18*100/Parametrar!B4) -> 9.7951624 | C18: =IF(Data!C18="","",Data!C18*100/Parametrar!B5) -> 14.487001
A19: =Data!A19 -> 17685 | B19: =IF(Data!B19="","",Data!B19*100/Parametrar!B4) -> 9.852277 | C19: =IF(Data!C19="","",Data!C19*100/Parametrar!B5) -> 14.675501
A20: =Data!A20 -> 17715 | B20: =IF(Data!B20="","",Data!B20*100/Parametrar!B4) -> 9.9542675 | C20: =IF(Data!C20="","",Data!C20*100/Parametrar!B5) -> 14.675501
A21: =Data!A21 -> 17746 | B21: =IF(Data!B21="","",Data!B21*100/Parametrar!B4) -> 9.9665063 | C21: =IF(Data!C21="","",Data!C21*100/Parametrar!B5) -> 14.621601
A22: =Data!A22 -> 17777 | B22: =IF(Data!B22="","",Data!B22*100/Parametrar!B4) -> 9.937949 | C22: =IF(Data!C22="","",Data!C22*100/Parametrar!B5) -> 14.513901
A23: =Data!A23 -> 17807 | B23: =IF(Data!B23="","",Data!B23*100/Parametrar!B4) -> 9.9175509 | C23: =IF(Data!C23="","",Data!C23*100/Parametrar!B5) -> 14.621701
A24: =Data!A24 -> 17838 | B24: =IF(Data!B24="","",Data!B24*100/Parametrar!B4) -> 9.8563567 | C24: =IF(Data!C24="","",Data!C24*100/Parametrar!B5) -> 14.433201
A25: =Data!A25 -> 17868 | B25: =IF(Data!B25="","",Data!B25*100/Parametrar!B4) -> 9.8114809 | C25: =IF(Data!C25="","",Data!C25*100/Parametrar!B5) -> 14.298501
A26: =Data!A26 -> 17899 | B26: =IF(Data!B26="","",Data!B26*100/Parametrar!B4) -> 9.7951624 | C26: =IF(Data!C26="","",Data!C26*100/Parametrar!B5) -> 14.163901
A27: =Data!A27 -> 17930 | B27: =IF(Data!B27="","",Data!B27*100/Parametrar!B4) -> 9.7543662 | C27: =IF(Data!C27="","",Data!C27*100/Parametrar!B5) -> 14.029201
A28: =Data!A28 -> 17958 | B28: =IF(Data!B28="","",Data!B28*100/Parametrar!B4) -> 9.7543662 | C28: =IF(Data!C28="","",Data!C28*100/Parametrar!B5) -> 13.760001
A29: =Data!A29 -> 17989 | B29: =IF(Data!B29="","",Data!B29*100/Parametrar!B4) -> 9.7584458 | C29: =IF(Data!C29="","",Data!C29*100/Parametrar!B5) -> 13.679201
A30: =Data!A30 -> 18019 | B30: =IF(Data!B30="","",Data!B30*100/Parametrar!B4) -> 9.7543662 | C30: =IF(Data!C30="","",Data!C30*100/Parametrar!B5) -> 13.490701
A31: =Data!A31 -> 18050 | B31: =IF(Data!B31="","",Data!B31*100/Parametrar!B4) -> 9.7584458 | C31: =IF(Data!C31="","",Data!C31*100/Parametrar!B5) -> 13.463801
A32: =Data!A32 -> 18080 | B32: =IF(Data!B32="","",Data!B32*100/Parametrar!B4) -> 9.6686942 | C32: =IF(Data!C32="","",Data!C32*100/Parametrar!B5) -> 13.436801
A33: =Data!A33 -> 18111 | B33: =IF(Data!B33="","",Data!B33*100/Parametrar!B4) -> 9.6686942 | C33: =IF(Data!C33="","",Data!C33*100/Parametrar!B5) -> 13.571501
A34: =Data!A34 -> 18142 | B34: =IF(Data!B34="","",Data!B34*100/Parametrar!B4) -> 9.6890923 | C34: =IF(Data!C34="","",Data!C34*100/Parametrar!B5) -> 13.706101
A35: =Data!A35 -> 18172 | B35: =IF(Data!B35="","",Data!B35*100/Parametrar!B4) -> 9.6564554 | C35: =IF(Data!C35="","",Data!C35*100/Parametrar!B5) -> 13.194501
A36: =Data!A36 -> 18203 | B36: =IF(Data!B36="","",Data!B36*100/Parametrar!B4) -> 9.6686942 | C36: =IF(Data!C36="","",Data!C36*100/Parametrar!B5) -> 13.544601
A37: =Data!A37 -> 18233 | B37: =IF(Data!B37="","",Data!B37*100/Parametrar!B4) -> 9.6319777 | C37: =IF(Data!C37="","",Data!C37*100/Parametrar!B5) -> 13.786901
A38: =Data!A38 -> 18264 | B38: =IF(Data!B38="","",Data!B38*100/Parametrar!B4) -> 9.5911815 | C38: =IF(Data!C38="","",Data!C38*100/Parametrar!B5) -> 14.029201
A39: =Data!A39 -> 18295 | B39: =IF(Data!B39="","",Data!B39*100/Parametrar!B4) -> 9.6319777 | C39: =IF(Data!C39="","",Data!C39*100/Parametrar!B5) -> 14.083101
A40: =Data!A40 -> 18323 | B40: =IF(Data!B40="","",Data!B40*100/Parametrar!B4) -> 9.6442165 | C40: =IF(Data!C40="","",Data!C40*100/Parametrar!B5) -> 14.540901
...

Sheet MoM
A1: DatumA1:F1 | B1: CPI MoM (%) | C1: INDPRO MoM (%) | D1: INDPRO SMA 3 | E1: SMA 3 CPI | F1: Stdev INDPRO | G1: Stdev CPI | H1: 0.32 Stdev INDPRO | I1: c | J1: c*std INDPRO | K1: c*std CPI | L1: 0.32 Stdev INDPRO | M1: 0.32 Stdev CPI | P1: Direkt från datan utifrån SMA | Q1: Med min duration 3 mån | R1: INDPRO grundriktning | S1: INDPRO riktning med buffert 0,32 | T1: CPI grundriktning | U1: CPI riktning med buffert 0,32 | V1: Med buffert 0,32 * std | W1: Min duration 3 mån reducerad | X1: Buffert 0,20 reducerad | Y1: NBER
A2: =Data!A2 -> 17168 | B2: =IFERROR((Data!B2/Data!B1-1)*100,"") | C2: =IFERROR((Data!C2/Data!C1-1)*100,"")
A3: =Data!A3 -> 17199 | B3: =IFERROR((Data!B3/Data!B2-1)*100,"") -> 0.65176909 | C3: =IFERROR((Data!C3/Data!C2-1)*100,"") -> 0.59067782
A4: =Data!A4 -> 17227 | B4: =IFERROR((Data!B4/Data!B3-1)*100,"") -> 1.7576318 | C4: =IFERROR((Data!C4/Data!C3-1)*100,"") -> 0.58648256
A5: =Data!A5 -> 17258 | B5: =IFERROR((Data!B5/Data!B4-1)*100,"") -> 0 | C5: =IFERROR((Data!C5/Data!C4-1)*100,"") -> -0.77813983 | D5: =SUM(C3:C5)/3 -> 0.13300685 | E5: =SUM(B3:B5)/3 -> 0.80313364 | F5: =_xlfn.STDEV.P(C3:C951) -> 1.064249 | G5: =_xlfn.STDEV.P(B3:B951) -> 3.2732212 | H5: =0.32*F5 -> 0.34055968 | I5: 0.05 | J5: =I5*$F$5 -> 0.05321245 | K5: =I5*$G$5 -> 0.16366106 | L5: =0.32*F5 -> 0.34055968 | M5: =0.32*G5 -> 1.0474308 | P5: {=_xlfn.IFS( AND(D5>0,E5>0),"Expansion", AND(D5<0,E5>0),"Slowdown", AND(D5<0,E5<0),"Contraction", AND(D5>0,E5<0),"Recovery", TRUE,"Undefined" )} -> Expansion | Q5: Expansion | R5: =IF(D5>-0.26, 1, -1) -> 1 | S5: =IF(R5=1, IF(D5 < -$L$5, -1, 1), IF(D5 > $L$5, 1, -1)) -> 1 | T5: =IF(E5>0, 1, -1) -> 1 | U5: =IF(T5=1, IF(E5 < -$M$5, -1, 1), IF(E5 > $M$5, 1, -1)) -> 1 | V5: {=_xlfn.IFS( AND(S5>0,U5>0),"Expansion", AND(S5<0,U5>0),"Slowdown", AND(S5<0,U5<0),"Contraction", AND(S5>0,U5<0),"Recovery", TRUE,"Undefined" )} -> Expansion | W5: =IF(Q5="Contraction", 1, 0) -> 0 | X5: =IF(V5="Contraction", 1, 0) -> 0 | Y5: 0
A6: =Data!A6 -> 17288 | B6: =IFERROR((Data!B6/Data!B5-1)*100,"") -> -0.22727273 | C6: =IFERROR((Data!C6/Data!C5-1)*100,"") -> 0.39248525 | D6: =SUM(C4:C6)/3 -> 0.06694266 | E6: =SUM(B4:B6)/3 -> 0.5101197 | I6: 0.1 | J6: =I6*$F$5 -> 0.1064249 | K6: =I6*$G$5 -> 0.32732212 | P6: {=_xlfn.IFS( AND(D6>0,E6>0),"Expansion", AND(D6<0,E6>0),"Slowdown", AND(D6<0,E6<0),"Contraction", AND(D6>0,E6<0),"Recovery", TRUE,"Undefined" )} -> Expansion | Q6: Expansion | R6: =IF(D6>-0.26, 1, -1) -> 1 | S6: =IF(R6=1, IF(D6 < -$L$5, -1, 1), IF(D6 > $L$5, 1, -1)) -> 1 | T6: =IF(E6>0, 1, -1) -> 1 | U6: =IF(T6=1, IF(E6 < -$M$5, -1, 1), IF(E6 > $M$5, 1, -1)) -> 1 | V6: {=_xlfn.IFS( AND(S6>0,U6>0),"Expansion", AND(S6<0,U6>0),"Slowdown", AND(S6<0,U6<0),"Contraction", AND(S6>0,U6<0),"Recovery", TRUE,"Undefined" )} -> Expansion | W6: =IF(Q6="Contraction", 1, 0) -> 0 | X6: =IF(V6="Contraction", 1, 0) -> 0 | Y6: 0
A7: =Data!A7 -> 17319 | B7: =IFERROR((Data!B7/Data!B6-1)*100,"") -> 0.59225513 | C7: =IFERROR((Data!C7/Data!C6-1)*100,"") -> 0 | D7: =SUM(C5:C7)/3 -> -0.12855153 | E7: =SUM(B5:B7)/3 -> 0.1216608 | I7: 0.15 | J7: =I7*$F$5 -> 0.15963735 | K7: =I7*$G$5 -> 0.49098318 | P7: {=_xlfn.IFS( AND(D7>0,E7>0),"Expansion", AND(D7<0,E7>0),"Slowdown", AND(D7<0,E7<0),"Contraction", AND(D7>0,E7<0),"Recovery", TRUE,"Undefined" )} -> Slowdown | Q7: Expansion | R7: =IF(D7>-0.26, 1, -1) -> 1 | S7: =IF(R7=1, IF(D7 < -$L$5, -1, 1), IF(D7 > $L$5, 1, -1)) -> 1 | T7: =IF(E7>0, 1, -1) -> 1 | U7: =IF(T7=1, IF(E7 < -$M$5, -1, 1), IF(E7 > $M$5, 1, -1)) -> 1 | V7: {=_xlfn.IFS( AND(S7>0,U7>0),"Expansion", AND(S7<0,U7>0),"Slowdown", AND(S7<0,U7<0),"Contraction", AND(S7>0,U7<0),"Recovery", TRUE,"Undefined" )} -> Expansion | W7: =IF(Q7="Contraction", 1, 0) -> 0 | X7: =IF(V7="Contraction", 1, 0) -> 0 | Y7: 0
A8: =Data!A8 -> 17349 | B8: =IFERROR((Data!B8/Data!B7-1)*100,"") -> 0.67934783 | C8: =IFERROR((Data!C8/Data!C7-1)*100,"") -> -0.58606358 | D8: =SUM(C6:C8)/3 -> -0.064526109 | E8: =SUM(B6:B8)/3 -> 0.34811007 | I8: 0.2 | J8: =I8*$F$5 -> 0.2128498 | K8: =I8*$G$5 -> 0.65464424 | P8: {=_xlfn.IFS( AND(D8>0,E8>0),"Expansion", AND(D8<0,E8>0),"Slowdown", AND(D8<0,E8<0),"Contraction", AND(D8>0,E8<0),"Recovery", TRUE,"Undefined" )} -> Slowdown | Q8: Expansion | R8: =IF(D8>-0.26, 1, -1) -> 1 | S8: =IF(R8=1, IF(D8 < -$L$5, -1, 1), IF(D8 > $L$5, 1, -1)) -> 1 | T8: =IF(E8>0, 1, -1) -> 1 | U8: =IF(T8=1, IF(E8 < -$M$5, -1, 1), IF(E8 > $M$5, 1, -1)) -> 1 | V8: {=_xlfn.IFS( AND(S8>0,U8>0),"Expansion", AND(S8<0,U8>0),"Slowdown", AND(S8<0,U8<0),"Contraction", AND(S8>0,U8<0),"Recovery", TRUE,"Undefined" )} -> Expansion | W8: =IF(Q8="Contraction", 1, 0) -> 0 | X8: =IF(V8="Contraction", 1, 0) -> 0 | Y8: 0
A9: =Data!A9 -> 17380 | B9: =IFERROR((Data!B9/Data!B8-1)*100,"") -> 0.76473234 | C9: =IFERROR((Data!C9/Data!C8-1)*100,"") -> 0.58951854 | D9: =SUM(C7:C9)/3 -> 0.0011516511 | E9: =SUM(B7:B9)/3 -> 0.67877843 | I9: 0.25 | J9: =I9*$F$5 -> 0.26606225 | K9: =I9*$G$5 -> 0.8183053 | P9: {=_xlfn.IFS( AND(D9>0,E9>0),"Expansion", AND(D9<0,E9>0),"Slowdown", AND(D9<0,E9<0),"Contraction", AND(D9>0,E9<0),"Recovery", TRUE,"Undefined" )} -> Expansion | Q9: Expansion | R9: =IF(D9>-0.26, 1, -1) -> 1 | S9: =IF(R9=1, IF(D9 < -$L$5, -1, 1), IF(D9 > $L$5, 1, -1)) -> 1 | T9: =IF(E9>0, 1, -1) -> 1 | U9: =IF(T9=1, IF(E9 < -$M$5, -1, 1), IF(E9 > $M$5, 1, -1)) -> 1 | V9: {=_xlfn.IFS( AND(S9>0,U9>0),"Expansion", AND(S9<0,U9>0),"Slowdown", AND(S9<0,U9<0),"Contraction", AND(S9>0,U9<0),"Recovery", TRUE,"Undefined" )} -> Expansion | W9: =IF(Q9="Contraction", 1, 0) -> 0 | X9: =IF(V9="Contraction", 1, 0) -> 0 | Y9: 0
A10: =Data!A10 -> 17411 | B10: =IFERROR((Data!B10/Data!B9-1)*100,"") -> 1.9642857 | C10: =IFERROR((Data!C10/Data!C9-1)*100,"") -> 0.78117633 | D10: =SUM(C8:C10)/3 -> 0.26154376 | E10: =SUM(B8:B10)/3 -> 1.136122 | I10: 0.3 | J10: =I10*$F$5 -> 0.3192747 | K10: =I10*$G$5 -> 0.98196636 | P10: {=_xlfn.IFS( AND(D10>0,E10>0),"Expansion", AND(D10<0,E10>0),"Slowdown", AND(D10<0,E10<0),"Contraction", AND(D10>0,E10<0),"Recovery", TRUE,"Undefined" )} -> Expansion | Q10: Expansion | R10: =IF(D10>-0.26, 1, -1) -> 1 | S10: =IF(R10=1, IF(D10 < -$L$5, -1, 1), IF(D10 > $L$5, 1, -1)) -> 1 | T10: =IF(E10>0, 1, -1) -> 1 | U10: =IF(T10=1, IF(E10 < -$M$5, -1, 1), IF(E10 > $M$5, 1, -1)) -> 1 | V10: {=_xlfn.IFS( AND(S10>0,U10>0),"Expansion", AND(S10<0,U10>0),"Slowdown", AND(S10<0,U10<0),"Contraction", AND(S10>0,U10<0),"Recovery", TRUE,"Undefined" )} -> Expansion | W10: =IF(Q10="Contraction", 1, 0) -> 0 | X10: =IF(V10="Contraction", 1, 0) -> 0 | Y10: 0
A11: =Data!A11 -> 17441 | B11: =IFERROR((Data!B11/Data!B10-1)*100,"") -> 0.30647986 | C11: =IFERROR((Data!C11/Data!C10-1)*100,"") -> 0.96872166 | D11: =SUM(C9:C11)/3 -> 0.77980551 | E11: =SUM(B9:B11)/3 -> 1.0118326 | I11: 0.35 | J11: =I11*$F$5 -> 0.37248715 | K11: =I11*$G$5 -> 1.1456274 | P11: {=_xlfn.IFS( AND(D11>0,E11>0),"Expansion", AND(D11<0,E11>0),"Slowdown", AND(D11<0,E11<0),"Contraction", AND(D11>0,E11<0),"Recovery", TRUE,"Undefined" )} -> Expansion | Q11: =IF(AND(P11=P10, P10=P9), P11, Q10) -> Expansion | R11: =IF(D11>-0.26, 1, -1) -> 1 | S11: =IF(R11=1, IF(D11 < -$L$5, -1, 1), IF(D11 > $L$5, 1, -1)) -> 1 | T11: =IF(E11>0, 1, -1) -> 1 | U11: =IF(T11=1, IF(E11 < -$M$5, -1, 1), IF(E11 > $M$5, 1, -1)) -> 1 | V11: {=_xlfn.IFS( AND(S11>0,U11>0),"Expansion", AND(S11<0,U11>0),"Slowdown", AND(S11<0,U11<0),"Contraction", AND(S11>0,U11<0),"Recovery", TRUE,"Undefined" )} -> Expansion | W11: =IF(Q11="Contraction", 1, 0) -> 0 | X11: =IF(V11="Contraction", 1, 0) -> 0 | Y11: 0
A12: =Data!A12 -> 17472 | B12: =IFERROR((Data!B12/Data!B11-1)*100,"") -> 0.65473592 | C12: =IFERROR((Data!C12/Data!C11-1)*100,"") -> 1.3436262 | D12: =SUM(C10:C12)/3 -> 1.0311747 | E12: =SUM(B10:B12)/3 -> 0.97516717 | I12: 0.4 | J12: =I12*$F$5 -> 0.4256996 | K12: =I12*$G$5 -> 1.3092885 | P12: {=_xlfn.IFS( AND(D12>0,E12>0),"Expansion", AND(D12<0,E12>0),"Slowdown", AND(D12<0,E12<0),"Contraction", AND(D12>0,E12<0),"Recovery", TRUE,"Undefined" )} -> Expansion | Q12: =IF(AND(P12=P11, P11=P10), P12, Q11) -> Expansion | R12: =IF(D12>-0.26, 1, -1) -> 1 | S12: =IF(R12=1, IF(D12 < -$L$5, -1, 1), IF(D12 > $L$5, 1, -1)) -> 1 | T12: =IF(E12>0, 1, -1) -> 1 | U12: =IF(T12=1, IF(E12 < -$M$5, -1, 1), IF(E12 > $M$5, 1, -1)) -> 1 | V12: {=_xlfn.IFS( AND(S12>0,U12>0),"Expansion", AND(S12<0,U12>0),"Slowdown", AND(S12<0,U12<0),"Contraction", AND(S12>0,U12<0),"Recovery", TRUE,"Undefined" )} -> Expansion | W12: =IF(Q12="Contraction", 1, 0) -> 0 | X12: =IF(V12="Contraction", 1, 0) -> 0 | Y12: 0
A13: =Data!A13 -> 17502 | B13: =IFERROR((Data!B13/Data!B12-1)*100,"") -> 1.5177797 | C13: =IFERROR((Data!C13/Data!C12-1)*100,"") -> 0.37910492 | D13: =SUM(C11:C13)/3 -> 0.89715091 | E13: =SUM(B11:B13)/3 -> 0.82633183 | I13: 0.45 | J13: =I13*$F$5 -> 0.47891205 | K13: =I13*$G$5 -> 1.4729495 | P13: {=_xlfn.IFS( AND(D13>0,E13>0),"Expansion", AND(D13<0,E13>0),"Slowdown", AND(D13<0,E13<0),"Contraction", AND(D13>0,E13<0),"Recovery", TRUE,"Undefined" )} -> Expansion | Q13: =IF(AND(P13=P12, P12=P11), P13, Q12) -> Expansion | R13: =IF(D13>-0.26, 1, -1) -> 1 | S13: =IF(R13=1, IF(D13 < -$L$5, -1, 1), IF(D13 > $L$5, 1, -1)) -> 1 | T13: =IF(E13>0, 1, -1) -> 1 | U13: =IF(T13=1, IF(E13 < -$M$5, -1, 1), IF(E13 > $M$5, 1, -1)) -> 1 | V13: {=_xlfn.IFS( AND(S13>0,U13>0),"Expansion", AND(S13<0,U13>0),"Slowdown", AND(S13<0,U13<0),"Contraction", AND(S13>0,U13<0),"Recovery", TRUE,"Undefined" )} -> Expansion | W13: =IF(Q13="Contraction", 1, 0) -> 0 | X13: =IF(V13="Contraction", 1, 0) -> 0 | Y13: 0
A14: =Data!A14 -> 17533 | B14: =IFERROR((Data!B14/Data!B13-1)*100,"") -> 1.1533533 | C14: =IFERROR((Data!C14/Data!C13-1)*100,"") -> 0.56615937 | D14: =SUM(C12:C14)/3 -> 0.76296348 | E14: =SUM(B12:B14)/3 -> 1.108623 | I14: 0.5 | J14: =I14*$F$5 -> 0.5321245 | K14: =I14*$G$5 -> 1.6366106 | P14: {=_xlfn.IFS( AND(D14>0,E14>0),"Expansion", AND(D14<0,E14>0),"Slowdown", AND(D14<0,E14<0),"Contraction", AND(D14>0,E14<0),"Recovery", TRUE,"Undefined" )} -> Expansion | Q14: =IF(AND(P14=P13, P13=P12), P14, Q13) -> Expansion | R14: =IF(D14>-0.26, 1, -1) -> 1 | S14: =IF(R14=1, IF(D14 < -$L$5, -1, 1), IF(D14 > $L$5, 1, -1)) -> 1 | T14: =IF(E14>0, 1, -1) -> 1 | U14: =IF(T14=1, IF(E14 < -$M$5, -1, 1), IF(E14 > $M$5, 1, -1)) -> 1 | V14: {=_xlfn.IFS( AND(S14>0,U14>0),"Expansion", AND(S14<0,U14>0),"Slowdown", AND(S14<0,U14<0),"Contraction", AND(S14>0,U14<0),"Recovery", TRUE,"Undefined" )} -> Expansion | W14: =IF(Q14="Contraction", 1, 0) -> 0 | X14: =IF(V14="Contraction", 1, 0) -> 0 | Y14: 0
A15: =Data!A15 -> 17564 | B15: =IFERROR((Data!B15/Data!B14-1)*100,"") -> -0.04222973 | C15: =IFERROR((Data!C15/Data!C14-1)*100,"") -> 0.1874251 | D15: =SUM(C13:C15)/3 -> 0.37756313 | E15: =SUM(B13:B15)/3 -> 0.87630108 | I15: 0.55 | J15: =I15*$F$5 -> 0.58533695 | K15: =I15*$G$5 -> 1.8002717 | P15: {=_xlfn.IFS( AND(D15>0,E15>0),"Expansion", AND(D15<0,E15>0),"Slowdown", AND(D15<0,E15<0),"Contraction", AND(D15>0,E15<0),"Recovery", TRUE,"Undefined" )} -> Expansion | Q15: =IF(AND(P15=P14, P14=P13), P15, Q14) -> Expansion | R15: =IF(D15>-0.26, 1, -1) -> 1 | S15: =IF(R15=1, IF(D15 < -$L$5, -1, 1), IF(D15 > $L$5, 1, -1)) -> 1 | T15: =IF(E15>0, 1, -1) -> 1 | U15: =IF(T15=1, IF(E15 < -$M$5, -1, 1), IF(E15 > $M$5, 1, -1)) -> 1 | V15: {=_xlfn.IFS( AND(S15>0,U15>0),"Expansion", AND(S15<0,U15>0),"Slowdown", AND(S15<0,U15<0),"Contraction", AND(S15>0,U15<0),"Recovery", TRUE,"Undefined" )} -> Expansion | W15: =IF(Q15="Contraction", 1, 0) -> 0 | X15: =IF(V15="Contraction", 1, 0) -> 0 | Y15: 0
A16: =Data!A16 -> 17593 | B16: =IFERROR((Data!B16/Data!B15-1)*100,"") -> -0.7182087 | C16: =IFERROR((Data!C16/Data!C15-1)*100,"") -> -1.1238377 | D16: =SUM(C14:C16)/3 -> -0.12341776 | E16: =SUM(B14:B16)/3 -> 0.13097161 | I16: 0.6 | J16: =I16*$F$5 -> 0.6385494 | K16: =I16*$G$5 -> 1.9639327 | P16: {=_xlfn.IFS( AND(D16>0,E16>0),"Expansion", AND(D16<0,E16>0),"Slowdown", AND(D16<0,E16<0),"Contraction", AND(D16>0,E16<0),"Recovery", TRUE,"Undefined" )} -> Slowdown | Q16: =IF(AND(P16=P15, P15=P14), P16, Q15) -> Expansion | R16: =IF(D16>-0.26, 1, -1) -> 1 | S16: =IF(R16=1, IF(D16 < -$L$5, -1, 1), IF(D16 > $L$5, 1, -1)) -> 1 | T16: =IF(E16>0, 1, -1) -> 1 | U16: =IF(T16=1, IF(E16 < -$M$5, -1, 1), IF(E16 > $M$5, 1, -1)) -> 1 | V16: {=_xlfn.IFS( AND(S16>0,U16>0),"Expansion", AND(S16<0,U16>0),"Slowdown", AND(S16<0,U16<0),"Contraction", AND(S16>0,U16<0),"Recovery", TRUE,"Undefined" )} -> Expansion | W16: =IF(Q16="Contraction", 1, 0) -> 0 | X16: =IF(V16="Contraction", 1, 0) -> 0 | Y16: 0
A17: =Data!A17 -> 17624 | B17: =IFERROR((Data!B17/Data!B16-1)*100,"") -> 1.3617021 | C17: =IFERROR((Data!C17/Data!C16-1)*100,"") -> 0.18990413 | D17: =SUM(C15:C17)/3 -> -0.24883617 | E17: =SUM(B15:B17)/3 -> 0.20042123 | I17: 0.65 | J17: =I17*$F$5 -> 0.69176185 | K17: =I17*$G$5 -> 2.1275938 | P17: {=_xlfn.IFS( AND(D17>0,E17>0),"Expansion", AND(D17<0,E17>0),"Slowdown", AND(D17<0,E17<0),"Contraction", AND(D17>0,E17<0),"Recovery", TRUE,"Undefined" )} -> Slowdown | Q17: =IF(AND(P17=P16, P16=P15), P17, Q16) -> Expansion | R17: =IF(D17>-0.26, 1, -1) -> 1 | S17: =IF(R17=1, IF(D17 < -$L$5, -1, 1), IF(D17 > $L$5, 1, -1)) -> 1 | T17: =IF(E17>0, 1, -1) -> 1 | U17: =IF(T17=1, IF(E17 < -$M$5, -1, 1), IF(E17 > $M$5, 1, -1)) -> 1 | V17: {=_xlfn.IFS( AND(S17>0,U17>0),"Expansion", AND(S17<0,U17>0),"Slowdown", AND(S17<0,U17<0),"Contraction", AND(S17>0,U17<0),"Recovery", TRUE,"Undefined" )} -> Expansion | W17: =IF(Q17="Contraction", 1, 0) -> 0 | X17: =IF(V17="Contraction", 1, 0) -> 0 | Y17: 0
A18: =Data!A18 -> 17654 | B18: =IFERROR((Data!B18/Data!B17-1)*100,"") -> 0.79764903 | C18: =IFERROR((Data!C18/Data!C17-1)*100,"") -> 1.7009835 | D18: =SUM(C16:C18)/3 -> 0.25568331 | E18: =SUM(B16:B18)/3 -> 0.48038082 | I18: 0.7 | J18: =I18*$F$5 -> 0.7449743 | K18: =I18*$G$5 -> 2.2912548 | P18: {=_xlfn.IFS( AND(D18>0,E18>0),"Expansion", AND(D18<0,E18>0),"Slowdown", AND(D18<0,E18<0),"Contraction", AND(D18>0,E18<0),"Recovery", TRUE,"Undefined" )} -> Expansion | Q18: =IF(AND(P18=P17, P17=P16), P18, Q17) -> Expansion | R18: =IF(D18>-0.26, 1, -1) -> 1 | S18: =IF(R18=1, IF(D18 < -$L$5, -1, 1), IF(D18 > $L$5, 1, -1)) -> 1 | T18: =IF(E18>0, 1, -1) -> 1 | U18: =IF(T18=1, IF(E18 < -$M$5, -1, 1), IF(E18 > $M$5, 1, -1)) -> 1 | V18: {=_xlfn.IFS( AND(S18>0,U18>0),"Expansion", AND(S18<0,U18>0),"Slowdown", AND(S18<0,U18<0),"Contraction", AND(S18>0,U18<0),"Recovery", TRUE,"Undefined" )} -> Expansion | W18: =IF(Q18="Contraction", 1, 0) -> 0 | X18: =IF(V18="Contraction", 1, 0) -> 0 | Y18: 0
A19: =Data!A19 -> 17685 | B19: =IFERROR((Data!B19/Data!B18-1)*100,"") -> 0.58309038 | C19: =IFERROR((Data!C19/Data!C18-1)*100,"") -> 1.3011666 | D19: =SUM(C17:C19)/3 -> 1.0640181 | E19: =SUM(B17:B19)/3 -> 0.91414718 | I19: 0.75 | J19: =I19*$F$5 -> 0.79818674 | K19: =I19*$G$5 -> 2.4549159 | P19: {=_xlfn.IFS( AND(D19>0,E19>0),"Expansion", AND(D19<0,E19>0),"Slowdown", AND(D19<0,E19<0),"Contraction", AND(D19>0,E19<0),"Recovery", TRUE,"Undefined" )} -> Expansion | Q19: =IF(AND(P19=P18, P18=P17), P19, Q18) -> Expansion | R19: =IF(D19>-0.26, 1, -1) -> 1 | S19: =IF(R19=1, IF(D19 < -$L$5, -1, 1), IF(D19 > $L$5, 1, -1)) -> 1 | T19: =IF(E19>0, 1, -1) -> 1 | U19: =IF(T19=1, IF(E19 < -$M$5, -1, 1), IF(E19 > $M$5, 1, -1)) -> 1 | V19: {=_xlfn.IFS( AND(S19>0,U19>0),"Expansion", AND(S19<0,U19>0),"Slowdown", AND(S19<0,U19<0),"Contraction", AND(S19>0,U19<0),"Recovery", TRUE,"Undefined" )} -> Expansion | W19: =IF(Q19="Contraction", 1, 0) -> 0 | X19: =IF(V19="Contraction", 1, 0) -> 0 | Y19: 0
A20: =Data!A20 -> 17715 | B20: =IFERROR((Data!B20/Data!B19-1)*100,"") -> 1.0351967 | C20: =IFERROR((Data!C20/Data!C19-1)*100,"") -> 0 | D20: =SUM(C18:C20)/3 -> 1.0007167 | E20: =SUM(B18:B20)/3 -> 0.80531203 | I20: 0.8 | J20: =I20*$F$5 -> 0.85139919 | K20: =I20*$G$5 -> 2.618577 | P20: {=_xlfn.IFS( AND(D20>0,E20>0),"Expansion", AND(D20<0,E20>0),"Slowdown", AND(D20<0,E20<0),"Contraction", AND(D20>0,E20<0),"Recovery", TRUE,"Undefined" )} -> Expansion | Q20: =IF(AND(P20=P19, P19=P18), P20, Q19) -> Expansion | R20: =IF(D20>-0.26, 1, -1) -> 1 | S20: =IF(R20=1, IF(D20 < -$L$5, -1, 1), IF(D20 > $L$5, 1, -1)) -> 1 | T20: =IF(E20>0, 1, -1) -> 1 | U20: =IF(T20=1, IF(E20 < -$M$5, -1, 1), IF(E20 > $M$5, 1, -1)) -> 1 | V20: {=_xlfn.IFS( AND(S20>0,U20>0),"Expansion", AND(S20<0,U20>0),"Slowdown", AND(S20<0,U20<0),"Contraction", AND(S20>0,U20<0),"Recovery", TRUE,"Undefined" )} -> Expansion | W20: =IF(Q20="Contraction", 1, 0) -> 0 | X20: =IF(V20="Contraction", 1, 0) -> 0 | Y20: 0
A21: =Data!A21 -> 17746 | B21: =IFERROR((Data!B21/Data!B20-1)*100,"") -> 0.12295082 | C21: =IFERROR((Data!C21/Data!C20-1)*100,"") -> -0.3672788 | D21: =SUM(C19:C21)/3 -> 0.31129592 | E21: =SUM(B19:B21)/3 -> 0.58041263 | I21: 0.85 | J21: =I21*$F$5 -> 0.90461164 | K21: =I21*$G$5 -> 2.782238 | P21: {=_xlfn.IFS( AND(D21>0,E21>0),"Expansion", AND(D21<0,E21>0),"Slowdown", AND(D21<0,E21<0),"Contraction", AND(D21>0,E21<0),"Recovery", TRUE,"Undefined" )} -> Expansion | Q21: =IF(AND(P21=P20, P20=P19), P21, Q20) -> Expansion | R21: =IF(D21>-0.26, 1, -1) -> 1 | S21: =IF(R21=1, IF(D21 < -$L$5, -1, 1), IF(D21 > $L$5, 1, -1)) -> 1 | T21: =IF(E21>0, 1, -1) -> 1 | U21: =IF(T21=1, IF(E21 < -$M$5, -1, 1), IF(E21 > $M$5, 1, -1)) -> 1 | V21: {=_xlfn.IFS( AND(S21>0,U21>0),"Expansion", AND(S21<0,U21>0),"Slowdown", AND(S21<0,U21<0),"Contraction", AND(S21>0,U21<0),"Recovery", TRUE,"Undefined" )} -> Expansion | W21: =IF(Q21="Contraction", 1, 0) -> 0 | X21: =IF(V21="Contraction", 1, 0) -> 0 | Y21: 0
A22: =Data!A22 -> 17777 | B22: =IFERROR((Data!B22/Data!B21-1)*100,"") -> -0.28653295 | C22: =IFERROR((Data!C22/Data!C21-1)*100,"") -> -0.7365815 | D22: =SUM(C20:C22)/3 -> -0.36795343 | E22: =SUM(B20:B22)/3 -> 0.29053819 | I22: 0.9 | J22: =I22*$F$5 -> 0.95782409 | K22: =I22*$G$5 -> 2.9458991 | P22: {=_xlfn.IFS( AND(D22>0,E22>0),"Expansion", AND(D22<0,E22>0),"Slowdown", AND(D22<0,E22<0),"Contraction", AND(D22>0,E22<0),"Recovery", TRUE,"Undefined" )} -> Slowdown | Q22: =IF(AND(P22=P21, P21=P20), P22, Q21) -> Expansion | R22: =IF(D22>-0.26, 1, -1) -> -1 | S22: =IF(R22=1, IF(D22 < -$L$5, -1, 1), IF(D22 > $L$5, 1, -1)) -> -1 | T22: =IF(E22>0, 1, -1) -> 1 | U22: =IF(T22=1, IF(E22 < -$M$5, -1, 1), IF(E22 > $M$5, 1, -1)) -> 1 | V22: {=_xlfn.IFS( AND(S22>0,U22>0),"Expansion", AND(S22<0,U22>0),"Slowdown", AND(S22<0,U22<0),"Contraction", AND(S22>0,U22<0),"Recovery", TRUE,"Undefined" )} -> Slowdown | W22: =IF(Q22="Contraction", 1, 0) -> 0 | X22: =IF(V22="Contraction", 1, 0) -> 0 | Y22: 0
... A24: =Data!A24 -> 17838 | B24: =IFERROR((Data!B24/Data!B23-1)*100,"") -> -0.61703003 | C24: =IFERROR((Data!C24/Data!C23-1)*100,"") -> -1.2891798 | D24: =SUM(C22:C24)/3 -> -0.427675 | E24: =SUM(B22:B24)/3 -> -0.36960583 | I24: 1 | J24: =I24*$F$5 -> 1.064249 | K24: =I24*$G$5 -> 3.2732212 | P24: {=_xlfn.IFS( AND(D24>0,E24>0),"Expansion", AND(D24<0,E24>0),"Slowdown", AND(D24<0,E24<0),"Contraction", AND(D24>0,E24<0),"Recovery", TRUE,"Undefined" )} -> Contraction | Q24: =IF(AND(P24=P23, P23=P22), P24, Q23) -> Expansion | R24: =IF(D24>-0.26, 1, -1) -> -1 | S24: =IF(R24=1, IF(D24 < -$L$5, -1, 1), IF(D24 > $L$5, 1, -1)) -> -1 | T24: =IF(E24>0, 1, -1) -> -1 | U24: =IF(T24=1, IF(E24 < -$M$5, -1, 1), IF(E24 > $M$5, 1, -1)) -> -1 | V24: {=_xlfn.IFS( AND(S24>0,U24>0),"Expansion", AND(S24<0,U24>0),"Slowdown", AND(S24<0,U24<0),"Contraction", AND(S24>0,U24<0),"Recovery", TRUE,"Undefined" )} -> Contraction | W24: =IF(Q24="Contraction", 1, 0) -> 0 | X24: =IF(V24="Contraction", 1, 0) -> 1 | Y24: 0
A25: =Data!A25 -> 17868 | B25: =IFERROR((Data!B25/Data!B24-1)*100,"") -> -0.45529801 | C25: =IFERROR((Data!C25/Data!C24-1)*100,"") -> -0.93326497 | D25: =SUM(C23:C25)/3 -> -0.49323616 | E25: =SUM(B23:B25)/3 -> -0.42586085 | P25: {=_xlfn.IFS( AND(D25>0,E25>0),"Expansion", AND(D25<0,E25>0),"Slowdown", AND(D25<0,E25<0),"Contraction", AND(D25>0,E25<0),"Recovery", TRUE,"Undefined" )} -> Contraction | Q25: =IF(AND(P25=P24, P24=P23), P25, Q24) -> Contraction | R25: =IF(D25>-0.26, 1, -1) -> -1 | S25: =IF(R25=1, IF(D25 < -$L$5, -1, 1), IF(D25 > $L$5, 1, -1)) -> -1 | T25: =IF(E25>0, 1, -1) -> -1 | U25: =IF(T25=1, IF(E25 < -$M$5, -1, 1), IF(E25 > $M$5, 1, -1)) -> -1 | V25: {=_xlfn.IFS( AND(S25>0,U25>0),"Expansion", AND(S25<0,U25>0),"Slowdown", AND(S25<0,U25<0),"Contraction", AND(S25>0,U25<0),"Recovery", TRUE,"Undefined" )} -> Contraction | W25: =IF(Q25="Contraction", 1, 0) -> 1 | X25: =IF(V25="Contraction", 1, 0) -> 1 | Y25: 1
A26: =Data!A26 -> 17899 | B26: =IFERROR((Data!B26/Data!B25-1)*100,"") -> -0.16632017 | C26: =IFERROR((Data!C26/Data!C25-1)*100,"") -> -0.94135749 | D26: =SUM(C24:C26)/3 -> -1.0546007 | E26: =SUM(B24:B26)/3 -> -0.41288274 | P26: {=_xlfn.IFS( AND(D26>0,E26>0),"Expansion", AND(D26<0,E26>0),"Slowdown", AND(D26<0,E26<0),"Contraction", AND(D26>0,E26<0),"Recovery", TRUE,"Undefined" )} -> Contraction | Q26: =IF(AND(P26=P25, P25=P24), P26, Q25) -> Contraction | R26: =IF(D26>-0.26, 1, -1) -> -1 | S26: =IF(R26=1, IF(D26 < -$L$5, -1, 1), IF(D26 > $L$5, 1, -1)) -> -1 | T26: =IF(E26>0, 1, -1) -> -1 | U26: =IF(T26=1, IF(E26 < -$M$5, -1, 1), IF(E26 > $M$5, 1, -1)) -> -1 | V26: {=_xlfn.IFS( AND(S26>0,U26>0),"Expansion", AND(S26<0,U26>0),"Slowdown", AND(S26<0,U26<0),"Contraction", AND(S26>0,U26<0),"Recovery", TRUE,"Undefined" )} -> Contraction | W26: =IF(Q26="Contraction", 1, 0) -> 1 | X26: =IF(V26="Contraction", 1, 0) -> 1 | Y26: 1
A27: =Data!A27 -> 17930 | B27: =IFERROR((Data!B27/Data!B26-1)*100,"") -> -0.41649313 | C27: =IFERROR((Data!C27/Data!C26-1)*100,"") -> -0.95100926 | D27: =SUM(C25:C27)/3 -> -0.94187724 | E27: =SUM(B25:B27)/3 -> -0.3460371 | P27: {=_xlfn.IFS( AND(D27>0,E27>0),"Expansion", AND(D27<0,E27>0),"Slowdown", AND(D27<0,E27<0),"Contraction", AND(D27>0,E27<0),"Recovery", TRUE,"Undefined" )} -> Contraction | Q27: =IF(AND(P27=P26, P26=P25), P27, Q26) -> Contraction | R27: =IF(D27>-0.26, 1, -1) -> -1 | S27: =IF(R27=1, IF(D27 < -$L$5, -1, 1), IF(D27 > $L$5, 1, -1)) -> -1 | T27: =IF(E27>0, 1, -1) -> -1 | U27: =IF(T27=1, IF(E27 < -$M$5, -1, 1), IF(E27 > $M$5, 1, -1)) -> -1 | V27: {=_xlfn.IFS( AND(S27>0,U27>0),"Expansion", AND(S27<0,U27>0),"Slowdown", AND(S27<0,U27<0),"Contraction", AND(S27>0,U27<0),"Recovery", TRUE,"Undefined" )} -> Contraction | W27: =IF(Q27="Contraction", 1, 0) -> 1 | X27: =IF(V27="Contraction", 1, 0) -> 1 | Y27: 1
A28: =Data!A28 -> 17958 | B28: =IFERROR((Data!B28/Data!B27-1)*100,"") -> 0 | C28: =IFERROR((Data!C28/Data!C27-1)*100,"") -> -1.918855 | D28: =SUM(C26:C28)/3 -> -1.2704072 | E28: =SUM(B26:B28)/3 -> -0.1942711 | P28: {=_xlfn.IFS( AND(D28>0,E28>0),"Expansion", AND(D28<0,E28>0),"Slowdown", AND(D28<0,E28<0),"Contraction", AND(D28>0,E28<0),"Recovery", TRUE,"Undefined" )} -> Contraction | Q28: =IF(AND(P28=P27, P27=P26), P28, Q27) -> Contraction | R28: =IF(D28>-0.26, 1, -1) -> -1 | S28: =IF(R28=1, IF(D28 < -$L$5, -1, 1), IF(D28 > $L$5, 1, -1)) -> -1 | T28: =IF(E28>0, 1, -1) -> -1 | U28: =IF(T28=1, IF(E28 < -$M$5, -1, 1), IF(E28 > $M$5, 1, -1)) -> -1 | V28: {=_xlfn.IFS( AND(S28>0,U28>0),"Expansion", AND(S28<0,U28>0),"Slowdown", AND(S28<0,U28<0),"Contraction", AND(S28>0,U28<0),"Recovery", TRUE,"Undefined" )} -> Contraction | W28: =IF(Q28="Contraction", 1, 0) -> 1 | X28: =IF(V28="Contraction", 1, 0) -> 1 | Y28: 1
A29: =Data!A29 -> 17989 | B29: =IFERROR((Data!B29/Data!B28-1)*100,"") -> 0.041823505 | C29: =IFERROR((Data!C29/Data!C28-1)*100,"") -> -0.5872093 | D29: =SUM(C27:C29)/3 -> -1.1523578 | E29: =SUM(B27:B29)/3 -> -0.12488987 | P29: {=_xlfn.IFS( AND(D29>0,E29>0),"Expansion", AND(D29<0,E29>0),"Slowdown", AND(D29<0,E29<0),"Contraction", AND(D29>0,E29<0),"Recovery", TRUE,"Undefined" )} -> Contraction | Q29: =IF(AND(P29=P28, P28=P27), P29, Q28) -> Contraction | R29: =IF(D29>-0.26, 1, -1) -> -1 | S29: =IF(R29=1, IF(D29 < -$L$5, -1, 1), IF(D29 > $L$5, 1, -1)) -> -1 | T29: =IF(E29>0, 1, -1) -> -1 | U29: =IF(T29=1, IF(E29 < -$M$5, -1, 1), IF(E29 > $M$5, 1, -1)) -> -1 | V29: {=_xlfn.IFS( AND(S29>0,U29>0),"Expansion", AND(S29<0,U29>0),"Slowdown", AND(S29<0,U29<0),"Contraction", AND(S29>0,U29<0),"Recovery", TRUE,"Undefined" )} -> Contraction | W29: =IF(Q29="Contraction", 1, 0) -> 1 | X29: =IF(V29="Contraction", 1, 0) -> 1 | Y29: 1
A30: =Data!A30 -> 18019 | B30: =IFERROR((Data!B30/Data!B29-1)*100,"") -> -0.04180602 | C30: =IFERROR((Data!C30/Data!C29-1)*100,"") -> -1.3780046 | D30: =SUM(C28:C30)/3 -> -1.2946896 | E30: =SUM(B28:B30)/3 -> 5.8282476e-06 | P30: {=_xlfn.IFS( AND(D30>0,E30>0),"Expansion", AND(D30<0,E30>0),"Slowdown", AND(D30<0,E30<0),"Contraction", AND(D30>0,E30<0),"Recovery", TRUE,"Undefined" )} -> Slowdown | Q30: =IF(AND(P30=P29, P29=P28), P30, Q29) -> Contraction | R30: =IF(D30>-0.26, 1, -1) -> -1 | S30: =IF(R30=1, IF(D30 < -$L$5, -1, 1), IF(D30 > $L$5, 1, -1)) -> -1 | T30: =IF(E30>0, 1, -1) -> 1 | U30: =IF(T30=1, IF(E30 < -$M$5, -1, 1), IF(E30 > $M$5, 1, -1)) -> 1 | V30: {=_xlfn.IFS( AND(S30>0,U30>0),"Expansion", AND(S30<0,U30>0),"Slowdown", AND(S30<0,U30<0),"Contraction", AND(S30>0,U30<0),"Recovery", TRUE,"Undefined" )} -> Slowdown | W30: =IF(Q30="Contraction", 1, 0) -> 1 | X30: =IF(V30="Contraction", 1, 0) -> 0 | Y30: 1
A31: =Data!A31 -> 18050 | B31: =IFERROR((Data!B31/Data!B30-1)*100,"") -> 0.041823505 | C31: =IFERROR((Data!C31/Data!C30-1)*100,"") -> -0.19939662 | D31: =SUM(C29:C31)/3 -> -0.72153683 | E31: =SUM(B29:B31)/3 -> 0.013946997 | P31: {=_xlfn.IFS( AND(D31>0,E31>0),"Expansion", AND(D31<0,E31>0),"Slowdown", AND(D31<0,E31<0),"Contraction", AND(D31>0,E31<0),"Recovery", TRUE,"Undefined" )} -> Slowdown | Q31: =IF(AND(P31=P30, P30=P29), P31, Q30) -> Contraction | R31: =IF(D31>-0.26, 1, -1) -> -1 | S31: =IF(R31=1, IF(D31 < -$L$5, -1, 1), IF(D31 > $L$5, 1, -1)) -> -1 | T31: =IF(E31>0, 1, -1) -> 1 | U31: =IF(T31=1, IF(E31 < -$M$5, -1, 1), IF(E31 > $M$5, 1, -1)) -> 1 | V31: {=_xlfn.IFS( AND(S31>0,U31>0),"Expansion", AND(S31<0,U31>0),"Slowdown", AND(S31<0,U31<0),"Contraction", AND(S31>0,U31<0),"Recovery", TRUE,"Undefined" )} -> Slowdown | W31: =IF(Q31="Contraction", 1, 0) -> 1 | X31: =IF(V31="Contraction", 1, 0) -> 0 | Y31: 1
A32: =Data!A32 -> 18080 | B32: =IFERROR((Data!B32/Data!B31-1)*100,"") -> -0.91973244 | C32: =IFERROR((Data!C32/Data!C31-1)*100,"") -> -0.20053774 | D32: =SUM(C30:C32)/3 -> -0.59264631 | E32: =SUM(B30:B32)/3 -> -0.30657165 | P32: {=_xlfn.IFS( AND(D32>0,E32>0),"Expansion", AND(D32<0,E32>0),"Slowdown", AND(D32<0,E32<0),"Contraction", AND(D32>0,E32<0),"Recovery", TRUE,"Undefined" )} -> Contraction | Q32: =IF(AND(P32=P31, P31=P30), P32, Q31) -> Contraction | R32: =IF(D32>-0.26, 1, -1) -> -1 | S32: =IF(R32=1, IF(D32 < -$L$5, -1, 1), IF(D32 > $L$5, 1, -1)) -> -1 | T32: =IF(E32>0, 1, -1) -> -1 | U32: =IF(T32=1, IF(E32 < -$M$5, -1, 1), IF(E32 > $M$5, 1, -1)) -> -1 | V32: {=_xlfn.IFS( AND(S32>0,U32>0),"Expansion", AND(S32<0,U32>0),"Slowdown", AND(S32<0,U32<0),"Contraction", AND(S32>0,U32<0),"Recovery", TRUE,"Undefined" )} -> Contraction | W32: =IF(Q32="Contraction", 1, 0) -> 1 | X32: =IF(V32="Contraction", 1, 0) -> 1 | Y32: 1
A33: =Data!A33 -> 18111 | B33: =IFERROR((Data!B33/Data!B32-1)*100,"") -> 0 | C33: =IFERROR((Data!C33/Data!C32-1)*100,"") -> 1.0024708 | D33: =SUM(C31:C33)/3 -> 0.20084549 | E33: =SUM(B31:B33)/3 -> -0.29263631 | P33: {=_xlfn.IFS( AND(D33>0,E33>0),"Expansion", AND(D33<0,E33>0),"Slowdown", AND(D33<0,E33<0),"Contraction", AND(D33>0,E33<0),"Recovery", TRUE,"Undefined" )} -> Recovery | Q33: =IF(AND(P33=P32, P32=P31), P33, Q32) -> Contraction | R33: =IF(D33>-0.26, 1, -1) -> 1 | S33: =IF(R33=1, IF(D33 < -$L$5, -1, 1), IF(D33 > $L$5, 1, -1)) -> 1 | T33: =IF(E33>0, 1, -1) -> -1 | U33: =IF(T33=1, IF(E33 < -$M$5, -1, 1), IF(E33 > $M$5, 1, -1)) -> -1 | V33: {=_xlfn.IFS( AND(S33>0,U33>0),"Expansion", AND(S33<0,U33>0),"Slowdown", AND(S33<0,U33<0),"Contraction", AND(S33>0,U33<0),"Recovery", TRUE,"Undefined" )} -> Recovery | W33: =IF(Q33="Contraction", 1, 0) -> 1 | X33: =IF(V33="Contraction", 1, 0) -> 0 | Y33: 1
A34: =Data!A34 -> 18142 | B34: =IFERROR((Data!B34/Data!B33-1)*100,"") -> 0.21097046 | C34: =IFERROR((Data!C34/Data!C33-1)*100,"") -> 0.99178425 | D34: =SUM(C32:C34)/3 -> 0.59790578 | E34: =SUM(B32:B34)/3 -> -0.23625399 | P34: {=_xlfn.IFS( AND(D34>0,E34>0),"Expansion", AND(D34<0,E34>0),"Slowdown", AND(D34<0,E34<0),"Contraction", AND(D34>0,E34<0),"Recovery", TRUE,"Undefined" )} -> Recovery | Q34: =IF(AND(P34=P33, P33=P32), P34, Q33) -> Contraction | R34: =IF(D34>-0.26, 1, -1) -> 1 | S34: =IF(R34=1, IF(D34 < -$L$5, -1, 1), IF(D34 > $L$5, 1, -1)) -> 1 | T34: =IF(E34>0, 1, -1) -> -1 | U34: =IF(T34=1, IF(E34 < -$M$5, -1, 1), IF(E34 > $M$5, 1, -1)) -> -1 | V34: {=_xlfn.IFS( AND(S34>0,U34>0),"Expansion", AND(S34<0,U34>0),"Slowdown", AND(S34<0,U34<0),"Contraction", AND(S34>0,U34<0),"Recovery", TRUE,"Undefined" )} -> Recovery | W34: =IF(Q34="Contraction", 1, 0) -> 1 | X34: =IF(V34="Contraction", 1, 0) -> 0 | Y34: 1
A35: =Data!A35 -> 18172 | B35: =IFERROR((Data!B35/Data!B34-1)*100,"") -> -0.33684211 | C35: =IFERROR((Data!C35/Data!C34-1)*100,"") -> -3.7326446 | D35: =SUM(C33:C35)/3 -> -0.57946317 | E35: =SUM(B33:B35)/3 -> -0.041957214 | P35: {=_xlfn.IFS( AND(D35>0,E35>0),"Expansion", AND(D35<0,E35>0),"Slowdown", AND(D35<0,E35<0),"Contraction", AND(D35>0,E35<0),"Recovery", TRUE,"Undefined" )} -> Contraction | Q35: =IF(AND(P35=P34, P34=P33), P35, Q34) -> Contraction | R35: =IF(D35>-0.26, 1, -1) -> -1 | S35: =IF(R35=1, IF(D35 < -$L$5, -1, 1), IF(D35 > $L$5, 1, -1)) -> -1 | T35: =IF(E35>0, 1, -1) -> -1 | U35: =IF(T35=1, IF(E35 < -$M$5, -1, 1), IF(E35 > $M$5, 1, -1)) -> -1 | V35: {=_xlfn.IFS( AND(S35>0,U35>0),"Expansion", AND(S35<0,U35>0),"Slowdown", AND(S35<0,U35<0),"Contraction", AND(S35>0,U35<0),"Recovery", TRUE,"Undefined" )} -> Contraction | W35: =IF(Q35="Contraction", 1, 0) -> 1 | X35: =IF(V35="Contraction", 1, 0) -> 1 | Y35: 1
A36: =Data!A36 -> 18203 | B36: =IFERROR((Data!B36/Data!B35-1)*100,"") -> 0.12674271 | C36: =IFERROR((Data!C36/Data!C35-1)*100,"") -> 2.6533783 | D36: =SUM(C34:C36)/3 -> -0.029160678 | E36: =SUM(B34:B36)/3 -> 0.00029035706 | P36: {=_xlfn.IFS( AND(D36>0,E36>0),"Expansion", AND(D36<0,E36>0),"Slowdown", AND(D36<0,E36<0),"Contraction", AND(D36>0,E36<0),"Recovery", TRUE,"Undefined" )} -> Slowdown | Q36: =IF(AND(P36=P35, P35=P34), P36, Q35) -> Contraction | R36: =IF(D36>-0.26, 1, -1) -> 1 | S36: =IF(R36=1, IF(D36 < -$L$5, -1, 1), IF(D36 > $L$5, 1, -1)) -> 1 | T36: =IF(E36>0, 1, -1) -> 1 | U36: =IF(T36=1, IF(E36 < -$M$5, -1, 1), IF(E36 > $M$5, 1, -1)) -> 1 | V36: {=_xlfn.IFS( AND(S36>0,U36>0),"Expansion", AND(S36<0,U36>0),"Slowdown", AND(S36<0,U36<0),"Contraction", AND(S36>0,U36<0),"Recovery", TRUE,"Undefined" )} -> Expansion | W36: =IF(Q36="Contraction", 1, 0) -> 1 | X36: =IF(V36="Contraction", 1, 0) -> 0 | Y36: 0
... A951: =Data!A951 -> 46054 | B951: =IFERROR((Data!B951/Data!B950-1)*100,"") -> 0.26700307 | C951: =IFERROR((Data!C951/Data!C950-1)*100,"") -> 0.15107968 | D951: =SUM(C949:C951)/3 -> 0.39025451 | E951: =SUM(B949:B951)/3 -> 0.24521138 | P951: {=_xlfn.IFS( AND(D951>0,E951>0),"Expansion", AND(D951<0,E951>0),"Slowdown", AND(D951<0,E951<0),"Contraction", AND(D951>0,E951<0),"Recovery", TRUE,"Undefined" )} -> Expansion | Q951: =IF(AND(P951=P950, P950=P949), P951, Q950) -> Expansion | R951: =IF(D951>-0.26, 1, -1) -> 1 | S951: =IF(R951=1, IF(D951 < -$L$5, -1, 1), IF(D951 > $L$5, 1, -1)) -> 1 | T951: =IF(E951>0, 1, -1) -> 1 | U951: =IF(T951=1, IF(E951 < -$M$5, -1, 1), IF(E951 > $M$5, 1, -1)) -> 1 | V951: {=_xlfn.IFS( AND(S951>0,U951>0),"Expansion", AND(S951<0,U951>0),"Slowdown", AND(S951<0,U951<0),"Contraction", AND(S951>0,U951<0),"Recovery", TRUE,"Undefined" )} -> Expansion | W951: =IF(Q951="Contraction", 1, 0) -> 0 | X951: =IF(V951="Contraction", 1, 0) -> 0 | Y951: 0

Sheet Markovserien
A4: Dates | B4: States
A5: 17258 | B5: Expansion
A6: 17288 | B6: Expansion
A7: 17319 | B7: Expansion
A8: 17349 | B8: Expansion
A9: 17380 | B9: Expansion
A10: 17411 | B10: Expansion
A11: 17441 | B11: Expansion
A12: 17472 | B12: Expansion
A13: 17502 | B13: Expansion
A14: 17533 | B14: Expansion
A15: 17564 | B15: Expansion
A16: 17593 | B16: Expansion
... A951: 46054 | B951: Expansion

Sheet Confusion
A1: Min duration 3 mån reducerad | B1: Buffert 0,20 reducerad | C1: NBER
A5: 0 | B5: 0 | C5: 0
A6: 0 | B6: 0 | C6: 0
A7: 0 | B7: 0 | C7: 0
A8: 0 | B8: 0 | C8: 0
A9: 0 | B9: 0 | C9: 0
A10: 0 | B10: 0 | C10: 0
A11: 0 | B11: 0 | C11: 0
A12: 0 | B12: 0 | C12: 0
A13: 0 | B13: 0 | C13: 0
A14: 0 | B14: 0 | C14: 0
A15: 0 | B15: 0 | C15: 0
A16: 0 | B16: 0 | C16: 0
... A951: 0 | B951: 0 | C951: 0
